Workbook
Name c_noms: #REF!
Name d_noms: #REF!
Name l_noms: OFFSET(d_noms,0,0,COUNTA(c_noms)-1,1)

Sheet Master_Chronostrat
A1: INTERNATIONAL STAGES - GTS2020
A2: Eon | B2: Era | C2: Period | D2: Sub-Period | E2: Epoch | F2: Sub-epoch | G2: Stage/Age | H2: Sub-stage/Sub-age | I2: Ma
A3: TOP | B3: TOP | C3: TOP | E3: TOP | F3: TOP | G3: TOP | I3: 0
E4: Anthropocene | F4: TOP | G4: TOP | I4: =100/1000000 -> 0.0001
F5: Lt | G5: Meghalayan | I5: 0.00425
F6: M | G6: Northgrippian | I6: 0.008236
E7: Holocene | F7: E | G7: Greenlandian | I7: 0.011784
F8: Lt | G8: Lt. Pleist. | I8: 0.13
F9: M | G9: Chibanian | I9: 0.773
G10: Calabrian | I10: 1.806
C11: Quaternary | E11: Pleistocene | F11: E | G11: Gelasian | I11: 2.58
F12: Lt | G12: Piacenzian | I12: 3.6
E13: Pliocene | F13: E | G13: Zanclean | I13: 5.335
G14: Messinian | I14: 7.25
F15: Lt | G15: Tortonian | I15: 11.625
G16: Serravallian | I16: 13.82
F17: M | G17: Langhian | I17: 15.99
G18: Burdigalian | I18: 20.45
C19: Neogene | E19: Miocene | F19: E | G19: Aquitanian | I19: 23.04
F20: Lt | G20: Chattian | I20: 27.28615
E21: Oligocene | F21: E | G21: Rupelian | I21: 33.90488
F22: Lt | G22: Priabonian | I22: 37.71
G23: Bartonian | I23: 41.03
F24: M | G24: Lutetian | I24: 48.0707
E25: Eocene | F25: E | G25: Ypresian | I25: 56.001
F26: Lt | G26: Thanetian | I26: 59.237
F27: M | G27: Selandian | I27: 61.663
B28: Cenozoic | C28: Paleogene | E28: Paleocene | F28: E | G28: Danian | H28: TOP | I28: 66.04
H29: Lt | I29: 69.91
G30: Maastrichtian | H30: E | I30: 72.17
H31: Lt | I31: 76.38
H32: M | I32: 80.64
G33: Campanian | H33: E | I33: 83.65
H34: Lt | I34: 84.54
H35: M | I35: 85.3
G36: Santonian | H36: E | I36: 85.7
H37: Lt | I37: 87.5
H38: M | I38: 88.09
G39: Coniacian | H39: E | I39: 89.39
H40: Lt | I40: 90.27
...

Sheet Geological stages
A1: Geologic units - calibration of its time span to International Stages from Base (in black) to Top (green)
A2: Period | B2: STAGE | C2: Rank | D2: Region | E2: Base | F2: TOP | G2: Comments | H2: Base calibration (via concatenation) | I2: Top calibration (via concatenation) | J2: BEGIN: % up in Reference ICS stage of: | K2: Decimal version | L2: Base within International Stage | M2: Recognized on 2020 ICS Chart | N2: Notation | O2: International Stage base | P2: END % up in Reference ICS stage of: | Q2: Decimal version | R2: Top within International Stage | S2: Synthesis | T2: % occuped if included in
B3: Today | O3: 0
A4: QUATERNARY | B4: Meghalayan | C4: Stage/Age | D4: Global standard | E4: =$O$4-J4*($O$4-$O$3) -> 0.00425 | F4: =$O$4-P4*($O$4-$O$3) -> 0 | G4: Type section is in a cave in North India | H4: =CONCATENATE(K4," percent up in ",L4," international stage") -> 0 percent up in Meghalayan international stage | I4: =CONCATENATE(Q4," percent up in ",R4," international stage") -> 100 percent up in Meghalayan international stage | J4: 0 | K4: =ROUND(J4*100,1) -> 0 | L4: Meghalayan | M4: Stratotype | N4: q7 | O4: =Master_Chronostrat!I5 -> 0.00425 | P4: 1 | Q4: =ROUND(P4*100,1) -> 100 | R4: Meghalayan | S4: Stratotype
A5: QUATERNARY | B5: Northgrippian | C5: Stage/Age | D5: Global standard | E5: =$O$5-J5*($O$5-$O$4) -> 0.008236 | F5: =$O$5-P5*($O$5-$O$4) -> 0.00425 | H5: =CONCATENATE(K5," percent up in ",L5," international stage") -> 0 percent up in Northgrippian international stage | I5: =CONCATENATE(Q5," percent up in ",R5," international stage") -> 100 percent up in Northgrippian international stage | J5: 0 | K5: =ROUND(J5*100,1) -> 0 | L5: Northgrippian | M5: Stratotype | N5: q6 | O5: =Master_Chronostrat!I6 -> 0.008236 | P5: 1 | Q5: =ROUND(P5*100,1) -> 100 | R5: Northgrippian | S5: Stratotype
A6: QUATERNARY | B6: Devensian | D6: Great Britain | E6: =$O$13-J6*($O$13-$O$5) -> 0.011784 | F6: =$O$13-P6*($O$13-$O$5) -> 0.011631291 | H6: =CONCATENATE(K6," percent up in ",L6," international stage") -> 0 percent up in Greenlandian international stage | I6: =CONCATENATE(Q6," percent up in ",R6," international stage") -> 4.3 percent up in Greenlandian international stage | J6: 0 | K6: =ROUND(J6*100,1) -> 0 | L6: Greenlandian | P6: 0.043040764 | Q6: =ROUND(P6*100,1) -> 4.3 | R6: Greenlandian | S6: Equivalent to the base of
A7: QUATERNARY | B7: Flandrian | E7: =$O$13-J7*($O$13-$O$5) -> 0.011784 | F7: =$O$4-P7*($O$4-$O$3) -> 0 | H7: =CONCATENATE(K7," percent up in ",L7," international stage") -> 0 percent up in Greenlandian international stage | I7: =CONCATENATE(Q7," percent up in ",R7," international stage") -> 100 percent up in Meghalayan international stage | J7: 0 | K7: =ROUND(J7*100,1) -> 0 | L7: Greenlandian | P7: 1 | Q7: =ROUND(P7*100,1) -> 100 | R7: Meghalayan | S7: Equivalent to
A8: QUATERNARY | B8: Hallian | D8: California | E8: =$O$13-J8*($O$13-$O$5) -> 0.011784 | F8: =$O$4-P8*($O$4-$O$3) -> 0 | H8: =CONCATENATE(K8," percent up in ",L8," international stage") -> 0 percent up in Greenlandian international stage | I8: =CONCATENATE(Q8," percent up in ",R8," international stage") -> 100 percent up in Meghalayan international stage | J8: 0 | K8: =ROUND(J8*100,1) -> 0 | L8: Greenlandian | P8: 1 | Q8: =ROUND(P8*100,1) -> 100 | R8: Meghalayan | S8: Equivalent to
A9: QUATERNARY | B9: Hawera | D9: New Zealand | E9: =$O$13-J9*($O$13-$O$5) -> 0.011784 | F9: =$O$4-P9*($O$4-$O$3) -> 0 | H9: =CONCATENATE(K9," percent up in ",L9," international stage") -> 0 percent up in Greenlandian international stage | I9: =CONCATENATE(Q9," percent up in ",R9," international stage") -> 100 percent up in Meghalayan international stage | J9: 0 | K9: =ROUND(J9*100,1) -> 0 | L9: Greenlandian | P9: 1 | Q9: =ROUND(P9*100,1) -> 100 | R9: Meghalayan | S9: Equivalent to
A10: QUATERNARY | B10: Haweran | D10: New Zealand | E10: =$O$13-J10*($O$13-$O$5) -> 0.011784 | F10: =$O$4-P10*($O$4-$O$3) -> 0 | H10: =CONCATENATE(K10," percent up in ",L10," international stage") -> 0 percent up in Greenlandian international stage | I10: =CONCATENATE(Q10," percent up in ",R10," international stage") -> 100 percent up in Meghalayan international stage | J10: 0 | K10: =ROUND(J10*100,1) -> 0 | L10: Greenlandian | P10: 1 | Q10: =ROUND(P10*100,1) -> 100 | R10: Meghalayan | S10: Equivalent to
A11: QUATERNARY | B11: Holocene | C11: Epoch | D11: Global standard | E11: =$O$13-J11*($O$13-$O$5) -> 0.011784 | F11: =$O$4-P11*($O$4-$O$3) -> 0 | H11: =CONCATENATE(K11," percent up in ",L11," international stage") -> 0 percent up in Greenlandian international stage | I11: =CONCATENATE(Q11," percent up in ",R11," international stage") -> 100 percent up in Meghalayan international stage | J11: 0 | K11: =ROUND(J11*100,1) -> 0 | L11: Greenlandian | M11: Stratotype | N11: Q2 | P11: 1 | Q11: =ROUND(P11*100,1) -> 100 | R11: Meghalayan | S11: Periode
A12: QUATERNARY | B12: Recent | E12: =$O$13-J12*($O$13-$O$5) -> 0.011784 | F12: =$O$4-P12*($O$4-$O$3) -> 0 | G12: Informal term | H12: =CONCATENATE(K12," percent up in ",L12," international stage") -> 0 percent up in Greenlandian international stage | I12: =CONCATENATE(Q12," percent up in ",R12," international stage") -> 100 percent up in Meghalayan international stage | J12: 0 | K12: =ROUND(J12*100,1) -> 0 | L12: Greenlandian | P12: 1 | Q12: =ROUND(P12*100,1) -> 100 | R12: Meghalayan | S12: Equivalent to
A13: QUATERNARY | B13: Greenlandian | C13: Stage/Age | D13: Global standard | E13: =$O$13-J13*($O$13-$O$5) -> 0.011784 | F13: =$O$13-P13*($O$13-$O$5) -> 0.008236 | H13: =CONCATENATE(K13," percent up in ",L13," international stage") -> 0 percent up in Greenlandian international stage | I13: =CONCATENATE(Q13," percent up in ",R13," international stage") -> 100 percent up in Greenlandian international stage | J13: 0 | K13: =ROUND(J13*100,1) -> 0 | L13: Greenlandian | M13: Stratotype | N13: q5 | O13: =Master_Chronostrat!I7 -> 0.011784 | P13: 1 | Q13: =ROUND(P13*100,1) -> 100 | R13: Greenlandian | S13: Stratotype
A14: QUATERNARY | B14: Wisconsinian | D14: North America | E14: =$O$26-J14*($O$26-$O$13) -> 0.077278949 | F14: =$O$13-P14*($O$13-$O$5) -> 0.010018271 | H14: =CONCATENATE(K14," percent up in ",L14," international stage") -> 44.6 percent up in Pleistocene Upper international stage | I14: =CONCATENATE(Q14," percent up in ",R14," international stage") -> 49.8 percent up in Greenlandian international stage | J14: 0.44597221 | K14: =ROUND(J14*100,1) -> 44.6 | L14: Pleistocene Upper | P14: 0.49766888 | Q14: =ROUND(P14*100,1) -> 49.8 | R14: Greenlandian | S14: Overlapping
A15: QUATERNARY | B15: Malanghuangtuan | D15: China | E15: =$O$26-J15*($O$26-$O$13) -> 0.1031226 | F15: =$O$13-P15*($O$13-$O$5) -> 0.010018271 | H15: =CONCATENATE(K15," percent up in ",L15," international stage") -> 22.7 percent up in Pleistocene Upper international stage | I15: =CONCATENATE(Q15," percent up in ",R15," international stage") -> 49.8 percent up in Greenlandian international stage | J15: 0.22735838 | K15: =ROUND(J15*100,1) -> 22.7 | L15: Pleistocene Upper | P15: 0.49766888 | Q15: =ROUND(P15*100,1) -> 49.8 | R15: Greenlandian | S15: Overlapping
A16: QUATERNARY | B16: Pontinian | D16: Italy | E16: =$O$26-J16*($O$26-$O$13) -> 0.1031226 | F16: =$O$13-P16*($O$13-$O$5) -> 0.010018271 | H16: =CONCATENATE(K16," percent up in ",L16," international stage") -> 22.7 percent up in Pleistocene Upper international stage | I16: =CONCATENATE(Q16," percent up in ",R16," international stage") -> 49.8 percent up in Greenlandian international stage | J16: 0.22735838 | K16: =ROUND(J16*100,1) -> 22.7 | L16: Pleistocene Upper | P16: 0.49766888 | Q16: =ROUND(P16*100,1) -> 49.8 | R16: Greenlandian | S16: Overlapping
A17: QUATERNARY | B17: Versilian | E17: =$O$26-J17*($O$26-$O$13) -> 0.11806045 | F17: =$O$4-P17*($O$4-$O$3) -> 0 | H17: =CONCATENATE(K17," percent up in ",L17," international stage") -> 10.1 percent up in Pleistocene Upper international stage | I17: =CONCATENATE(Q17," percent up in ",R17," international stage") -> 100 percent up in Meghalayan international stage | J17: 0.10099776 | K17: =ROUND(J17*100,1) -> 10.1 | L17: Pleistocene Upper | P17: 1 | Q17: =ROUND(P17*100,1) -> 100 | R17: Meghalayan | S17: Overlapping
A18: QUATERNARY | B18: Tubantian | E18: =$O$26-J18*($O$26-$O$13) -> 0.11966254 | F18: =$O$13-P18*($O$13-$O$5) -> 0.011631291 | H18: =CONCATENATE(K18," percent up in ",L18," international stage") -> 8.7 percent up in Pleistocene Upper international stage | I18: =CONCATENATE(Q18," percent up in ",R18," international stage") -> 4.3 percent up in Greenlandian international stage | J18: 0.087445532 | K18: =ROUND(J18*100,1) -> 8.7 | L18: Pleistocene Upper | P18: 0.043040764 | Q18: =ROUND(P18*100,1) -> 4.3 | R18: Greenlandian | S18: Overlapping
A19: QUATERNARY | B19: Weichselian | D19: Northern Europe | E19: =$O$26-J19*($O$26-$O$13) -> 0.11966254 | F19: =$O$13-P19*($O$13-$O$5) -> 0.011631291 | H19: =CONCATENATE(K19," percent up in ",L19," international stage") -> 8.7 percent up in Pleistocene Upper international stage | I19: =CONCATENATE(Q19," percent up in ",R19," international stage") -> 4.3 percent up in Greenlandian international stage | J19: 0.087445532 | K19: =ROUND(J19*100,1) -> 8.7 | L19: Pleistocene Upper | P19: 0.043040764 | Q19: =ROUND(P19*100,1) -> 4.3 | R19: Greenlandian | S19: Overlapping
A20: QUATERNARY | B20: Würm Glacial | D20: Alps | E20: =$O$26-J20*($O$26-$O$13) -> 0.11966254 | F20: =$O$13-P20*($O$13-$O$5) -> 0.011631291 | H20: =CONCATENATE(K20," percent up in ",L20," international stage") -> 8.7 percent up in Pleistocene Upper international stage | I20: =CONCATENATE(Q20," percent up in ",R20," international stage") -> 4.3 percent up in Greenlandian international stage | J20: 0.087445532 | K20: =ROUND(J20*100,1) -> 8.7 | L20: Pleistocene Upper | P20: 0.043040764 | Q20: =ROUND(P20*100,1) -> 4.3 | R20: Greenlandian | S20: Overlapping
A21: QUATERNARY | B21: Valdaian | D21: Russian Plain | E21: =$O$26-J21*($O$26-$O$13) -> 0.12793251 | F21: =$O$26-P21*($O$26-$O$13) -> 0.012152944 | H21: =CONCATENATE(K21," percent up in ",L21," international stage") -> 1.7 percent up in Pleistocene Upper international stage | I21: =CONCATENATE(Q21," percent up in ",R21," international stage") -> 99.7 percent up in Pleistocene Upper international stage | J21: 0.017489106 | K21: =ROUND(J21*100,1) -> 1.7 | L21: Pleistocene Upper | P21: 0.99687907 | Q21: =ROUND(P21*100,1) -> 99.7 | R21: Pleistocene Upper | S21: Include in | T21: 0.97938996
A22: QUATERNARY | B22: Sangamonian | D22: North America | E22: =$O$26-J22*($O$26-$O$13) -> 0.12896625 | F22: =$O$26-P22*($O$26-$O$13) -> 0.077278949 | H22: =CONCATENATE(K22," percent up in ",L22," international stage") -> 0.9 percent up in Pleistocene Upper international stage | I22: =CONCATENATE(Q22," percent up in ",R22," international stage") -> 44.6 percent up in Pleistocene Upper international stage | J22: 0.0087445532 | K22: =ROUND(J22*100,1) -> 0.9 | L22: Pleistocene Upper | P22: 0.44597221 | Q22: =ROUND(P22*100,1) -> 44.6 | R22: Pleistocene Upper | S22: Include in | T22: 0.43722766
A23: QUATERNARY | B23: Mikulinian | D23: Russian Plain | E23: =$O$26-J23*($O$26-$O$13) -> 0.13 | F23: =$O$26-P23*($O$26-$O$13) -> 0.12793251 | H23: =CONCATENATE(K23," percent up in ",L23," international stage") -> 0 percent up in Pleistocene Upper international stage | I23: =CONCATENATE(Q23," percent up in ",R23," international stage") -> 1.7 percent up in Pleistocene Upper international stage | J23: 0 | K23: =ROUND(J23*100,1) -> 0 | L23: Pleistocene Upper | P23: 0.017489106 | Q23: =ROUND(P23*100,1) -> 1.7 | R23: Pleistocene Upper | S23: Equivalent to the base of
A24: QUATERNARY | B24: Tarantian | D24: Italy | E24: =$O$26-J24*($O$26-$O$13) -> 0.13 | F24: =$O$26-P24*($O$26-$O$13) -> 0.011784 | H24: =CONCATENATE(K24," percent up in ",L24," international stage") -> 0 percent up in Pleistocene Upper international stage | I24: =CONCATENATE(Q24," percent up in ",R24," international stage") -> 100 percent up in Pleistocene Upper international stage | J24: 0 | K24: =ROUND(J24*100,1) -> 0 | L24: Pleistocene Upper | P24: 1 | Q24: =ROUND(P24*100,1) -> 100 | R24: Pleistocene Upper | S24: Equivalent to
A25: QUATERNARY | B25: Tyrrhenian | D25: Europe | E25: =$O$26-J25*($O$26-$O$13) -> 0.13 | F25: =$O$26-P25*($O$26-$O$13) -> 0.08253074 | H25: =CONCATENATE(K25," percent up in ",L25," international stage") -> 0 percent up in Pleistocene Upper international stage | I25: =CONCATENATE(Q25," percent up in ",R25," international stage") -> 40.2 percent up in Pleistocene Upper international stage | J25: 0 | K25: =ROUND(J25*100,1) -> 0 | L25: Pleistocene Upper | P25: 0.40154683 | Q25: =ROUND(P25*100,1) -> 40.2 | R25: Pleistocene Upper | S25: Equivalent to the base of
A26: QUATERNARY | B26: Pleistocene Upper | C26: Sub-epoch | D26: Global standard | E26: =$O$26-J26*($O$26-$O$13) -> 0.13 | F26: =$O$26-P26*($O$26-$O$13) -> 0.011784 | H26: =CONCATENATE(K26," percent up in ",L26," international stage") -> 0 percent up in Pleistocene Upper international stage | I26: =CONCATENATE(Q26," percent up in ",R26," international stage") -> 100 percent up in Pleistocene Upper international stage | J26: 0 | K26: =ROUND(J26*100,1) -> 0 | L26: Pleistocene Upper | M26: Stratotype | N26: q4 | O26: =Master_Chronostrat!I8 -> 0.13 | P26: 1 | Q26: =ROUND(P26*100,1) -> 100 | R26: Pleistocene Upper | S26: Stratotype
A27: QUATERNARY | B27: Riss-Würm Interglacial | D27: Alps | E27: =$O$76-J27*($O$76-$O$26) -> 0.13196336 | F27: =$O$26-P27*($O$26-$O$13) -> 0.11966254 | H27: =CONCATENATE(K27," percent up in ",L27," international stage") -> 99.7 percent up in Chibanian international stage | I27: =CONCATENATE(Q27," percent up in ",R27," international stage") -> 8.7 percent up in Pleistocene Upper international stage | J27: 0.99694656 | K27: =ROUND(J27*100,1) -> 99.7 | L27: Chibanian | P27: 0.087445532 | Q27: =ROUND(P27*100,1) -> 8.7 | R27: Pleistocene Upper | S27: Overlapping
A28: QUATERNARY | B28: Eemian | D28: Northern Europe | E28: =$O$76-J28*($O$76-$O$26) -> 0.13392672 | F28: =$O$26-P28*($O$26-$O$13) -> 0.11966254 | H28: =CONCATENATE(K28," percent up in ",L28," international stage") -> 99.4 percent up in Chibanian international stage | I28: =CONCATENATE(Q28," percent up in ",R28," international stage") -> 8.7 percent up in Pleistocene Upper international stage | J28: 0.99389313 | K28: =ROUND(J28*100,1) -> 99.4 | L28: Chibanian | P28: 0.087445532 | Q28: =ROUND(P28*100,1) -> 8.7 | R28: Pleistocene Upper | S28: Overlapping
A29: QUATERNARY | B29: Ipswichian | D29: Great Britain | E29: =$O$76-J29*($O$76-$O$26) -> 0.13392672 | F29: =$O$26-P29*($O$26-$O$13) -> 0.11966254 | H29: =CONCATENATE(K29," percent up in ",L29," international stage") -> 99.4 percent up in Chibanian international stage | I29: =CONCATENATE(Q29," percent up in ",R29," international stage") -> 8.7 percent up in Pleistocene Upper international stage | J29: 0.99389313 | K29: =ROUND(J29*100,1) -> 99.4 | L29: Chibanian | P29: 0.087445532 | Q29: =ROUND(P29*100,1) -> 8.7 | R29: Pleistocene Upper | S29: Overlapping
A30: QUATERNARY | B30: Warthian | D30: NW Europe | E30: =$O$76-J30*($O$76-$O$26) -> 0.15356031 | F30: =$O$76-P30*($O$76-$O$26) -> 0.13392672 | H30: =CONCATENATE(K30," percent up in ",L30," international stage") -> 96.3 percent up in Chibanian international stage | I30: =CONCATENATE(Q30," percent up in ",R30," international stage") -> 99.4 percent up in Chibanian international stage | J30: 0.96335878 | K30: =ROUND(J30*100,1) -> 96.3 | L30: Chibanian | P30: 0.99389313 | Q30: =ROUND(P30*100,1) -> 99.4 | R30: Chibanian | S30: Include in | T30: 0.030534351
A31: QUATERNARY | B31: Warthe | D31: NW Europe | E31: =$O$76-J31*($O$76-$O$26) -> 0.1633771 | F31: =$O$76-P31*($O$76-$O$26) -> 0.13 | H31: =CONCATENATE(K31," percent up in ",L31," international stage") -> 94.8 percent up in Chibanian international stage | I31: =CONCATENATE(Q31," percent up in ",R31," international stage") -> 100 percent up in Chibanian international stage | J31: 0.9480916 | K31: =ROUND(J31*100,1) -> 94.8 | L31: Chibanian | P31: 1 | Q31: =ROUND(P31*100,1) -> 100 | R31: Chibanian | S31: Equivalent to the top of
A32: QUATERNARY | B32: Illinoian | D32: North America | E32: =$O$76-J32*($O$76-$O$26) -> 0.17319389 | F32: =$O$26-P32*($O$26-$O$13) -> 0.12896625 | H32: =CONCATENATE(K32," percent up in ",L32," international stage") -> 93.3 percent up in Chibanian international stage | I32: =CONCATENATE(Q32," percent up in ",R32," international stage") -> 0.9 percent up in Pleistocene Upper international stage | J32: 0.93282443 | K32: =ROUND(J32*100,1) -> 93.3 | L32: Chibanian | P32: 0.0087445532 | Q32: =ROUND(P32*100,1) -> 0.9 | R32: Pleistocene Upper | S32: Overlapping
A33: QUATERNARY | B33: Treenean | D33: NW Europe | E33: =$O$76-J33*($O$76-$O$26) -> 0.17319389 | F33: =$O$76-P33*($O$76-$O$26) -> 0.15356031 | H33: =CONCATENATE(K33," percent up in ",L33," international stage") -> 93.3 percent up in Chibanian international stage | I33: =CONCATENATE(Q33," percent up in ",R33," international stage") -> 96.3 percent up in Chibanian international stage | J33: 0.93282443 | K33: =ROUND(J33*100,1) -> 93.3 | L33: Chibanian | P33: 0.96335878 | Q33: =ROUND(P33*100,1) -> 96.3 | R33: Chibanian | S33: Include in | T33: 0.030534351
A34: QUATERNARY | B34: Dnieper | D34: Russian Plain | E34: =$O$76-J34*($O$76-$O$26) -> 0.20264427 | F34: =$O$76-P34*($O$76-$O$26) -> 0.1633771 | H34: =CONCATENATE(K34," percent up in ",L34," international stage") -> 88.7 percent up in Chibanian international stage | I34: =CONCATENATE(Q34," percent up in ",R34," international stage") -> 94.8 percent up in Chibanian international stage | J34: 0.8870229 | K34: =ROUND(J34*100,1) -> 88.7 | L34: Chibanian | P34: 0.9480916 | Q34: =ROUND(P34*100,1) -> 94.8 | R34: Chibanian | S34: Include in | T34: 0.061068702
A35: QUATERNARY | B35: Drenthe | D35: NW Europe | E35: =$O$76-J35*($O$76-$O$26) -> 0.20264427 | F35: =$O$76-P35*($O$76-$O$26) -> 0.1633771 | H35: =CONCATENATE(K35," percent up in ",L35," international stage") -> 88.7 percent up in Chibanian international stage | I35: =CONCATENATE(Q35," percent up in ",R35," international stage") -> 94.8 percent up in Chibanian international stage | J35: 0.8870229 | K35: =ROUND(J35*100,1) -> 88.7 | L35: Chibanian | P35: 0.9480916 | Q35: =ROUND(P35*100,1) -> 94.8 | R35: Chibanian | S35: Include in | T35: 0.061068702
A36: QUATERNARY | B36: Drenthian | D36: NW Europe | E36: =$O$76-J36*($O$76-$O$26) -> 0.23994809 | F36: =$O$76-P36*($O$76-$O$26) -> 0.17319389 | H36: =CONCATENATE(K36," percent up in ",L36," international stage") -> 82.9 percent up in Chibanian international stage | I36: =CONCATENATE(Q36," percent up in ",R36," international stage") -> 93.3 percent up in Chibanian international stage | J36: 0.82900763 | K36: =ROUND(J36*100,1) -> 82.9 | L36: Chibanian | P36: 0.93282443 | Q36: =ROUND(P36*100,1) -> 93.3 | R36: Chibanian | S36: Include in | T36: 0.10381679
A37: QUATERNARY | B37: Riss Glacial | D37: Alps | E37: =$O$76-J37*($O$76-$O$26) -> 0.23994809 | F37: =$O$76-P37*($O$76-$O$26) -> 0.13196336 | H37: =CONCATENATE(K37," percent up in ",L37," international stage") -> 82.9 percent up in Chibanian international stage | I37: =CONCATENATE(Q37," percent up in ",R37," international stage") -> 99.7 percent up in Chibanian international stage | J37: 0.82900763 | K37: =ROUND(J37*100,1) -> 82.9 | L37: Chibanian | P37: 0.99694656 | Q37: =ROUND(P37*100,1) -> 99.7 | R37: Chibanian | S37: Include in | T37: 0.16793893
A38: QUATERNARY | B38: Saalian | D38: Northern Europe | E38: =$O$76-J38*($O$76-$O$26) -> 0.23994809 | F38: =$O$76-P38*($O$76-$O$26) -> 0.13196336 | H38: =CONCATENATE(K38," percent up in ",L38," international stage") -> 82.9 percent up in Chibanian international stage | I38: =CONCATENATE(Q38," percent up in ",R38," international stage") -> 99.7 percent up in Chibanian international stage | J38: 0.82900763 | K38: =ROUND(J38*100,1) -> 82.9 | L38: Chibanian | P38: 0.99694656 | Q38: =ROUND(P38*100,1) -> 99.7 | R38: Chibanian | S38: Include in | T38: 0.16793893
A39: QUATERNARY | B39: Wolstonian | D39: Great Britain | E39: =$O$76-J39*($O$76-$O$26) -> 0.23994809 | F39: =$O$76-P39*($O$76-$O$26) -> 0.13196336 | H39: =CONCATENATE(K39," percent up in ",L39," international stage") -> 82.9 percent up in Chibanian international stage | I39: =CONCATENATE(Q39," percent up in ",R39," international stage") -> 99.7 percent up in Chibanian international stage | J39: 0.82900763 | K39: =ROUND(J39*100,1) -> 82.9 | L39: Chibanian | P39: 0.99694656 | Q39: =ROUND(P39*100,1) -> 99.7 | R39: Chibanian | S39: Include in | T39: 0.16793893
A40: QUATERNARY | B40: Nomentanan | D40: Italy | E40: =$O$76-J40*($O$76-$O$26) -> 0.24191145 | F40: =$O$76-P40*($O$76-$O$26) -> 0.13392672 | H40: =CONCATENATE(K40," percent up in ",L40," international stage") -> 82.6 percent up in Chibanian international stage | I40: =CONCATENATE(Q40," percent up in ",R40," international stage") -> 99.4 percent up in Chibanian international stage | J40: 0.8259542 | K40: =ROUND(J40*100,1) -> 82.6 | L40: Chibanian | P40: 0.99389313 | Q40: =ROUND(P40*100,1) -> 99.4 | R40: Chibanian | S40: Include in | T40: 0.16793893
...
